Workbook

Sheet January
A1: Republic of the Philippines
A2: DON HONORIO VENTURA STATE UNIVERSITY
A3: Villa de Bacolor, Pampanga
A4: Office of Student Welfare and Formation
A5: HEALTH SERVICES UNIT
A6: SUMMARY OF MEDICAL CASES
A7: June 2026
B9: CATEGORY | C9: College of Education (COE) | D9: College of Business Studies (CBS) | E9: College of Hospitality & Tourism Management | F9: College of Computing Studies | G9: College of Industrial Technology | H9: FACULTY | I9: NASA | J9: TOTAL
A10: A. | B10: ALIMENTARY SYSTEM (Nausea, Vomiting, Hyperacidty, Heartburn, Dyspepsia, Infectious Diarrhea, Constipation) | C10: 0 | D10: 0 | E10: 0 | F10: 0 | G10: 0 | H10: 0 | I10: 0 | J10: 0
A11: B. | B11: RESPIRATORY SYSTEM (Cough, Colds, Fever, Bronchial Asthma, Difficulty of Breathing, Pneumonia) | C11: 0 | D11: 0 | E11: 0 | F11: 0 | G11: 0 | H11: 3 | I11: 3 | J11: =SUM(C11:I11) -> 6
A12: C. | B12: MUSCULO-SKELETAL SYSTEM (Osteoarthritis, Osteochondritis, Muscle and Joint Spasm, Sprain, Strain, Fracture, Dislocation) | C12: 0 | D12: 0 | E12: 0 | F12: 0 | G12: 0 | H12: 0 | I12: 0 | J12: =SUM(C12:I12) -> 0
A13: D. | B13: INTEGUMENTARY SYSTEM (Burns, Cuts, Abrasion, Laceration, Bruise, Puncture, Minor Surgery, Skin Diseases, Allergies, Infected Wound, Animal Bite) | C13: 0 | D13: 0 | E13: 0 | F13: 0 | G13: 0 | H13: 0 | I13: 0 | J13: =SUM(C13:I13) -> 0
A14: E. | B14: URINARY SYSTEM (UTI) | C14: 0 | D14: 0 | E14: 0 | F14: 0 | G14: 0 | H14: 0 | I14: 1 | J14: =SUM(C14:I14) -> 1
A15: F. | B15: METABOLIC ENDOCRINE SYSTEM (Diabetes, Hyperthyroidism, Hypothyroidism, Dyslipidemia) | C15: 0 | D15: 0 | E15: 0 | F15: 0 | G15: 0 | H15: 0 | I15: 0 | J15: =SUM(C15:I15) -> 0
A16: G. | B16: CARDIOVASCULAR SYSTEM (Chest pain, Hypertension, Hypotension, Arrhythmias, Bradycardia, Tachycardia) | C16: 0 | D16: 0 | E16: 0 | F16: 0 | G16: 0 | H16: 0 | I16: 0 | J16: 0
A17: H. | B17: EYES, EARS, NOSE & THROAT DISORDERS (Sty, Fungal or Bacterial Infection, Foreign body,Vertigo, Otitis Media/Externa, Sinusitis, Epistaxis, Pharyngitis, Laryngitis, Tonsillitis, Rhinitis) | C17: 0 | D17: 0 | E17: 0 | F17: 0 | G17: 0 | H17: 0 | I17: 0 | J17: =SUM(C17:I17) -> 0
A18: I. | B18: COMMUNICABLE DISEASES (Conjunctivitis, Boils, Measles, Chicken Pox, Mumps, Hepatitis, Tuberculosis, Leptospirosis, COVID Suspect, Viral Exanthem | C18: 0 | D18: 0 | E18: 0 | F18: 0 | G18: 0 | H18: 0 | I18: 0 | J18: =SUM(C18:I18) -> 0
A19: J. | B19: BLOOD DISORDERS (Anemia, Pallor, ) | C19: 0 | D19: 0 | E19: 0 | F19: 0 | G19: 0 | H19: 0 | I19: 0 | J19: =SUM(C19:I19) -> 0
A20: K. | B20: NEUROLOGICAL DISORDERS (Hyperventilation, Anxiety attack, Panic Attack, Headache, Migraine, Syncope, Dizziness, Epilepsy, Seizure, Insomnia) | C20: 0 | D20: 0 | E20: 0 | F20: 0 | G20: 0 | H20: 0 | I20: 0 | J20: =SUM(C20:I20) -> 0
A21: L. | B21: OB-GYNE CASES (Dysmenorrhea, Pregnancy, Polycystic Ovarian Syndrome, Menstrual Disorders) | C21: 0 | D21: 0 | E21: 0 | F21: 0 | G21: 0 | H21: 0 | I21: 0 | J21: =SUM(C21:I21) -> 0
A22: M. | B22: DENTAL CASES | C22: 0 | D22: 0 | E22: 0 | F22: 0 | G22: 0 | H22: 0 | I22: 0 | J22: =SUM(C22:I22) -> 0
A23: N. | B23: PHYSICAL EXAMINATIONS (Medical Certificate/Clearance Issued) | C23: 190 | D23: 120 | E23: 54 | F23: 41 | G23: 65 | H23: 0 | I23: 0 | J23: =SUM(C23:I23) -> 470 | K23: 0 | L23: 27
A24: O. | B24: REFERRALS (Laboratory and Diagnostic Test Request, Specialist) | C24: 0 | D24: 0 | E24: 0 | F24: 0 | G24: 0 | H24: 0 | I24: 0 | J24: =SUM(C24:I24) -> 0
A25: P. | B25: FOLLOW - UP CHECK-UP | C25: 0 | D25: 0 | E25: 0 | F25: 0 | G25: 0 | H25: 0 | I25: 0 | J25: =SUM(C25:I25) -> 0
A26: Q. | B26: OTHERS (Height,Weight, Blood Pressure Monitoring, Prescription) | C26: 0 | D26: 0 | E26: 0 | F26: 0 | G26: 0 | H26: 0 | I26: 0 | J26: =SUM(C26:I26) -> 0
A27: R. | B27: Heat related cases | C27: 0 | D27: 0 | E27: 0 | F27: 0 | G27: 0 | H27: 0 | I27: 0 | J27: =SUM(C27:I27) -> 0
B28: TOTAL | C28: =SUM(C10:C27) -> 190 | D28: =SUM(D10:D27) -> 120 | E28: =SUM(E10:E27) -> 54 | F28: =SUM(F10:F27) -> 41 | G28: =SUM(G10:G27) -> 65 | H28: =SUM(H10:H27) -> 3 | I28: =SUM(I10:I27) -> 4 | J28: =SUM(C28:I28) -> 477
A30: Prepared by:
A32: LORELEI P. DATU,RN
B33: Nurse I
A36: Noted by:
A38: VICKY P. VITAL, EdD
A39: Director

Sheet February
A1: Republic of the Philippines
A2: DON HONORIO VENTURA STATE UNIVERSITY
A3: Villa de Bacolor, Pampanga
A4: Office of Student Welfare and Formation
A5: HEALTH SERVICES UNIT
A6: SUMMARY OF MEDICAL CASES
A7: ________________ 2025
B9: CATEGORY | C9: College of Education (COE) | D9: College of Business Studies (CBS) | E9: College of Hospitality & Tourism Management | F9: College of Computing Studies | G9: College of Industrial Technology | H9: FACULTY | I9: NASA | J9: TOTAL
A10: A. | B10: ALIMENTARY SYSTEM (Nausea, Vomiting, Hyperacidty, Heartburn, Dyspepsia, Infectious Diarrhea, Constipation) | C10: 8 | D10: 6 | E10: 1 | F10: 2 | G10: 9 | H10: 0 | I10: 1 | J10: =SUM(C10:I10) -> 27
A11: B. | B11: RESPIRATORY SYSTEM (Cough, Colds, Fever, Bronchial Asthma, Difficulty of Breathing, Pneumonia) | C11: 19 | D11: 9 | E11: 0 | F11: 4 | G11: 6 | H11: 7 | I11: 3 | J11: =SUM(C11:I11) -> 48
A12: C. | B12: MUSCULO-SKELETAL SYSTEM (Osteoarthritis, Osteochondritis, Muscle and Joint Spasm, Sprain, Strain, Fracture, Dislocation) | C12: 3 | D12: 2 | E12: 0 | F12: 2 | G12: 0 | H12: 0 | I12: 0 | J12: =SUM(C12:I12) -> 7
A13: D. | B13: INTEGUMENTARY SYSTEM (Burns, Cuts, Abrasion, Laceration, Bruise, Puncture, Minor Surgery, Skin Diseases, Allergies, Infected Wound, Animal Bite) | C13: 5 | D13: 0 | E13: 1 | F13: 1 | G13: 3 | H13: 0 | I13: 0 | J13: =SUM(C13:I13) -> 10
A14: E. | B14: URINARY SYSTEM (UTI) | C14: 0 | D14: 0 | E14: 0 | F14: 0 | G14: 0 | H14: 0 | I14: 1 | J14: =SUM(C14:I14) -> 1
A15: F. | B15: METABOLIC ENDOCRINE SYSTEM (Diabetes, Hyperthyroidism, Hypothyroidism, Dyslipidemia) | C15: 0 | D15: 0 | E15: 0 | F15: 0 | G15: 0 | H15: 0 | I15: 0 | J15: =SUM(C15:I15) -> 0
A16: G. | B16: CARDIOVASCULAR SYSTEM (Chest pain, Hypertension, Hypotension, Arrhythmias, Bradycardia, Tachycardia) | C16: 0 | D16: 1 | E16: 0 | F16: 0 | G16: 0 | H16: 0 | I16: 0 | J16: =SUM(C16:I16) -> 1
A17: H. | B17: EYES, EARS, NOSE & THROAT DISORDERS (Sty, Fungal or Bacterial Infection, Foreign body,Vertigo, Otitis Media/Externa, Sinusitis, Epistaxis, Pharyngitis, Laryngitis, Tonsillitis, Rhinitis) | C17: 0 | D17: 0 | E17: 0 | F17: 0 | G17: 0 | H17: 0 | I17: 0 | J17: =SUM(C17:I17) -> 0
A18: I. | B18: COMMUNICABLE DISEASES (Conjunctivitis, Boils, Measles, Chicken Pox, Mumps, Hepatitis, Tuberculosis, Leptospirosis, COVID Suspect, Viral Exanthem | C18: 0 | D18: 0 | E18: 0 | F18: 0 | G18: 0 | H18: 0 | I18: 0 | J18: =SUM(C18:I18) -> 0
A19: J. | B19: BLOOD DISORDERS (Anemia, Pallor, ) | C19: 0 | D19: 0 | E19: 0 | F19: 0 | G19: 0 | H19: 0 | I19: 0 | J19: =SUM(C19:I19) -> 0
A20: K. | B20: NEUROLOGICAL DISORDERS (Hyperventilation, Anxiety attack, Panic Attack, Headache, Migraine, Syncope, Dizziness, Epilepsy, Seizure, Insomnia) | C20: 15 | D20: 2 | E20: 0 | F20: 0 | G20: 2 | H20: 0 | I20: 0 | J20: =SUM(C20:I20) -> 19
A21: L. | B21: OB-GYNE CASES (Dysmenorrhea, Pregnancy, Polycystic Ovarian Syndrome, Menstrual Disorders) | C21: 4 | D21: 0 | E21: 0 | F21: 0 | G21: 0 | H21: 0 | I21: 0 | J21: =SUM(C21:I21) -> 4
... A27: R. | B27: Heat related cases | C27: 0 | D27: 0 | E27: 0 | F27: 0 | G27: 0 | H27: 0 | I27: 0 | J27: =SUM(C27:I27) -> 0
B28: TOTAL | C28: =SUM(C10:C27) -> 71 | D28: =SUM(D10:D27) -> 44 | E28: =SUM(E10:E27) -> 2 | F28: =SUM(F10:F27) -> 36 | G28: =SUM(G10:G27) -> 56 | H28: =SUM(H10:H27) -> 7 | I28: =SUM(I10:I27) -> 7 | J28: =SUM(C28:I28) -> 223
A30: Prepared by:
A32: LORELEI P. DATU, RN
A33: Nurse I
A36: Noted by:
A38: VICKY P. VITAL, EdD
A39: Director

Sheet March
A1: Republic of the Philippines
A2: DON HONORIO VENTURA STATE UNIVERSITY
A3: Villa de Bacolor, Pampanga
A4: Office of Student Welfare and Formation
A5: HEALTH SERVICES UNIT
A6: SUMMARY OF MEDICAL CASES
A7: ________________ 2025
B9: CATEGORY | C9: College of Education (COE) | D9: College of Business Studies (CBS) | E9: College of Hospitality & Tourism Management | F9: College of Computing Studies | G9: College of Industrial Technology | H9: FACULTY | I9: NASA | J9: TOTAL
A10: A. | B10: ALIMENTARY SYSTEM (Nausea, Vomiting, Hyperacidty, Heartburn, Dyspepsia, Infectious Diarrhea, Constipation) | C10: 9 | D10: 12 | E10: 0 | F10: 4 | G10: 4 | H10: 0 | I10: 0 | J10: =SUM(C10:I10) -> 29
A11: B. | B11: RESPIRATORY SYSTEM (Cough, Colds, Fever, Bronchial Asthma, Difficulty of Breathing, Pneumonia) | C11: 5 | D11: 5 | E11: 0 | F11: 3 | G11: 0 | H11: 0 | I11: 1 | J11: =SUM(C11:I11) -> 14
A12: C. | B12: MUSCULO-SKELETAL SYSTEM (Osteoarthritis, Osteochondritis, Muscle and Joint Spasm, Sprain, Strain, Fracture, Dislocation) | C12: 4 | D12: 0 | E12: 0 | F12: 0 | G12: 0 | H12: 0 | I12: 0 | J12: =SUM(C12:I12) -> 4
A13: D. | B13: INTEGUMENTARY SYSTEM (Burns, Cuts, Abrasion, Laceration, Bruise, Puncture, Minor Surgery, Skin Diseases, Allergies, Infected Wound, Animal Bite) | C13: 3 | D13: 5 | E13: 0 | F13: 0 | G13: 0 | H13: 0 | I13: 0 | J13: =SUM(C13:I13) -> 8
A14: E. | B14: URINARY SYSTEM (UTI) | C14: 0 | D14: 0 | E14: 0 | F14: 0 | G14: 1 | H14: 0 | I14: 1 | J14: =SUM(C14:I14) -> 2
A15: F. | B15: METABOLIC ENDOCRINE SYSTEM (Diabetes, Hyperthyroidism, Hypothyroidism, Dyslipidemia) | C15: 0 | D15: 0 | E15: 0 | F15: 0 | G15: 0 | H15: 0 | I15: 0 | J15: 0
A16: G. | B16: CARDIOVASCULAR SYSTEM (Chest pain, Hypertension, Hypotension, Arrhythmias, Bradycardia, Tachycardia) | C16: 0 | D16: 0 | E16: 0 | F16: 0 | G16: 0 | H16: 0 | I16: 0 | J16: 0
A17: H. | B17: EYES, EARS, NOSE & THROAT DISORDERS (Sty, Fungal or Bacterial Infection, Foreign body,Vertigo, Otitis Media/Externa, Sinusitis, Epistaxis, Pharyngitis, Laryngitis, Tonsillitis, Rhinitis) | C17: 0 | D17: 1 | E17: 0 | F17: 0 | G17: 0 | H17: 0 | I17: 0 | J17: =SUM(C17:I17) -> 1
A18: I. | B18: COMMUNICABLE DISEASES (Conjunctivitis, Boils, Measles, Chicken Pox, Mumps, Hepatitis, Tuberculosis, Leptospirosis, COVID Suspect, Viral Exanthem | C18: 0 | D18: 0 | E18: 0 | F18: 0 | G18: 1 | H18: 0 | I18: 0 | J18: =SUM(C18:I18) -> 1
A19: J. | B19: BLOOD DISORDERS (Anemia, Pallor, ) | C19: 0 | D19: 0 | E19: 0 | F19: 0 | G19: 0 | H19: 0 | I19: 0 | J19: 0
A20: K. | B20: NEUROLOGICAL DISORDERS (Hyperventilation, Anxiety attack, Panic Attack, Headache, Migraine, Syncope, Dizziness, Epilepsy, Seizure, Insomnia) | C20: 0 | D20: 0 | E20: 0 | F20: 0 | G20: 4 | H20: 0 | I20: 0 | J20: =SUM(C20:I20) -> 4
A21: L. | B21: OB-GYNE CASES (Dysmenorrhea, Pregnancy, Polycystic Ovarian Syndrome, Menstrual Disorders) | C21: 1 | D21: 1 | E21: 1 | F21: 1 | G21: 1 | H21: 0 | I21: 0 | J21: =SUM(C21:I21) -> 5
A22: M. | B22: DENTAL CASES | C22: 0 | D22: 0 | E22: 1 | F22: 1 | G22: 1 | H22: 0 | I22: 0 | J22: =SUM(C22:I22) -> 3
A23: N. | B23: PHYSICAL EXAMINATIONS (Medical Certificate/Clearance Issued) | C23: 0 | D23: 0 | E23: 0 | F23: 0 | G23: 0 | H23: 0 | I23: 0 | J23: =SUM(C23:I23) -> 0
A24: O. | B24: REFERRALS (Laboratory and Diagnostic Test Request, Specialist) | C24: 0 | D24: 0 | E24: 0 | F24: 0 | G24: 0 | H24: 0 | I24: 0 | J24: =SUM(C24:I24) -> 0
A25: P. | B25: FOLLOW - UP CHECK-UP | C25: 0 | D25: 0 | E25: 0 | F25: 0 | G25: 0 | H25: 0 | I25: 0 | J25: =SUM(C25:I25) -> 0
A26: Q. | B26: OTHERS (Height,Weight, Blood Pressure Monitoring, Prescription) | C26: 0 | D26: 1 | E26: 0 | F26: 0 | G26: 0 | H26: 0 | I26: 0 | J26: =SUM(C26:I26) -> 1
A27: R. | B27: Heat related cases | C27: 20 | D27: 14 | E27: 1 | F27: 8 | G27: 8 | H27: 0 | I27: 0 | J27: =SUM(C27:I27) -> 51
B28: TOTAL | C28: =SUM(C10:C27) -> 42 | D28: =SUM(D10:D27) -> 39 | E28: =SUM(E10:E27) -> 3 | F28: =SUM(F10:F27) -> 17 | G28: =SUM(G10:G27) -> 20 | H28: =SUM(H10:H27) -> 0 | I28: =SUM(I10:I27) -> 2 | J28: =SUM(J10:J27) -> 123
A30: Prepared by:
A32: ________________________________________
A33: Nurse I
A36: Noted by:
A38: ________________________________________
A39: Director

Sheet April
A1: Republic of the Philippines
A2: PAMPANGA STATE UNIVERSITY
A3: (former Don Honorio Ventura State University)
A5: Mexico Campus
A6: SUMMARY OF MEDICAL CASES
A7: ________________ 2025
B9: CATEGORY | C9: College of Education (COE) | D9: College of Business Studies (CBS) | E9: College of Hospitality & Tourism Management | F9: College of Computing Studies | G9: College of Industrial Technology | H9: FACULTY | I9: NASA | J9: TOTAL
A10: A. | B10: ALIMENTARY SYSTEM (Nausea, Vomiting, Hyperacidty, Heartburn, Dyspepsia, Infectious Diarrhea, Constipation) | C10: 9 | D10: 6 | E10: 0 | F10: 2 | G10: 0 | H10: 0 | I10: 0 | J10: =SUM(C10:I10) -> 17
A11: B. | B11: RESPIRATORY SYSTEM (Cough, Colds, Fever, Bronchial Asthma, Difficulty of Breathing, Pneumonia) | C11: 6 | D11: 5 | E11: 0 | F11: 3 | G11: 4 | H11: 0 | I11: 2 | J11: =SUM(C11:I11) -> 20
A12: C. | B12: MUSCULO-SKELETAL SYSTEM (Osteoarthritis, Osteochondritis, Muscle and Joint Spasm, Sprain, Strain, Fracture, Dislocation) | C12: 0 | D12: 0 | E12: 0 | F12: 1 | G12: 1 | H12: 0 | I12: 1 | J12: =SUM(C12:I12) -> 3
A13: D. | B13: INTEGUMENTARY SYSTEM (Burns, Cuts, Abrasion, Laceration, Bruise, Puncture, Minor Surgery, Skin Diseases, Allergies, Infected Wound, Animal Bite) | C13: 2 | D13: 0 | E13: 0 | F13: 0 | G13: 0 | H13: 0 | I13: 0 | J13: =SUM(C13:I13) -> 2
A14: E. | B14: URINARY SYSTEM (UTI) | C14: 2 | D14: 0 | E14: 0 | F14: 0 | G14: 0 | H14: 0 | I14: 0 | J14: =SUM(C14:I14) -> 2
A15: F. | B15: METABOLIC ENDOCRINE SYSTEM (Diabetes, Hyperthyroidism, Hypothyroidism, Dyslipidemia) | C15: 0 | D15: 0 | E15: 0 | F15: 0 | G15: 0 | H15: 0 | I15: 0 | J15: =SUM(C15:I15) -> 0
A16: G. | B16: CARDIOVASCULAR SYSTEM (Chest pain, Hypertension, Hypotension, Arrhythmias, Bradycardia, Tachycardia) | C16: 0 | D16: 0 | E16: 0 | F16: 0 | G16: 0 | H16: 0 | I16: 0 | J16: =SUM(C16:I16) -> 0
A17: H. | B17: EYES, EARS, NOSE & THROAT DISORDERS (Sty, Fungal or Bacterial Infection, Foreign body,Vertigo, Otitis Media/Externa, Sinusitis, Epistaxis, Pharyngitis, Laryngitis, Tonsillitis, Rhinitis) | C17: 2 | D17: 0 | E17: 0 | F17: 0 | G17: 0 | H17: 1 | I17: 0 | J17: =SUM(C17:I17) -> 3
A18: I. | B18: COMMUNICABLE DISEASES (Conjunctivitis, Boils, Measles, Chicken Pox, Mumps, Hepatitis, Tuberculosis, Leptospirosis, COVID Suspect, Viral Exanthem | C18: 0 | D18: 0 | E18: 0 | F18: 1 | G18: 1 | H18: 0 | I18: 0 | J18: =SUM(C18:I18) -> 2
A19: J. | B19: BLOOD DISORDERS (Anemia, Pallor, ) | C19: 0 | D19: 0 | E19: 0 | F19: 0 | G19: 0 | H19: 0 | I19: 0 | J19: =SUM(C19:I19) -> 0
A20: K. | B20: NEUROLOGICAL DISORDERS (Hyperventilation, Anxiety attack, Panic Attack, Headache, Migraine, Syncope, Dizziness, Epilepsy, Seizure, Insomnia) | C20: 0 | D20: 0 | E20: 0 | F20: 0 | G20: 0 | H20: 0 | I20: 1 | J20: =SUM(C20:I20) -> 1
A21: L. | B21: OB-GYNE CASES (Dysmenorrhea, Pregnancy, Polycystic Ovarian Syndrome, Menstrual Disorders) | C21: 4 | D21: 3 | E21: 0 | F21: 1 | G21: 0 | H21: 0 | I21: 0 | J21: =SUM(C21:I21) -> 8
... A27: R. | B27: Heat related cases | C27: 15 | D27: 8 | E27: 10 | F27: 1 | G27: 5 | H27: 1 | I27: 1 | J27: =SUM(C27:I27) -> 41
B28: TOTAL | C28: =SUM(C10:C27) -> 46 | D28: =SUM(D10:D27) -> 27 | E28: =SUM(E10:E27) -> 11 | F28: =SUM(F10:F27) -> 10 | G28: =SUM(G10:G27) -> 11 | H28: =SUM(H10:H27) -> 3 | I28: =SUM(I10:I27) -> 6 | J28: =SUM(C28:I28) -> 114
A30: Prepared by:
A32: ________________________________________
A33: Nurse I
A36: Noted by:
A38: ________________________________________
A39: Director

Sheet May
A1: Republic of the Philippines
A2: DON HONORIO VENTURA STATE UNIVERSITY
A3: Villa de Bacolor, Pampanga
A4: Office of Student Welfare and Formation
A5: HEALTH SERVICES UNIT
A6: SUMMARY OF MEDICAL CASES
A7: May 2026
B9: CATEGORY | C9: College of Education (COE) | D9: College of Business Studies (CBS) | E9: College of Hospitality & Tourism Management | F9: College of Computing Studies | G9: College of Industrial Technology | H9: FACULTY | I9: NASA | J9: TOTAL
A10: A. | B10: ALIMENTARY SYSTEM (Nausea, Vomiting, Hyperacidty, Heartburn, Dyspepsia, Infectious Diarrhea, Constipation) | C10: 12 | D10: 4 | E10: 1 | F10: 0 | G10: 0 | H10: 2 | I10: 2 | J10: =SUM(C10:I10) -> 21
A11: B. | B11: RESPIRATORY SYSTEM (Cough, Colds, Fever, Bronchial Asthma, Difficulty of Breathing, Pneumonia) | C11: 1 | D11: 0 | E11: 0 | F11: 0 | G11: 2 | H11: 1 | I11: 1 | J11: =SUM(C11:I11) -> 5
A12: C. | B12: MUSCULO-SKELETAL SYSTEM (Osteoarthritis, Osteochondritis, Muscle and Joint Spasm, Sprain, Strain, Fracture, Dislocation) | C12: 0 | D12: 0 | E12: 0 | F12: 0 | G12: 0 | H12: 0 | I12: 1 | J12: =SUM(C12:I12) -> 1
A13: D. | B13: INTEGUMENTARY SYSTEM (Burns, Cuts, Abrasion, Laceration, Bruise, Puncture, Minor Surgery, Skin Diseases, Allergies, Infected Wound, Animal Bite) | C13: 2 | D13: 0 | E13: 0 | F13: 0 | G13: 0 | H13: 0 | I13: 0 | J13: =SUM(C13:I13) -> 2
A14: E. | B14: URINARY SYSTEM (UTI) | C14: 0 | D14: 0 | E14: 0 | F14: 0 | G14: 0 | H14: 0 | I14: 0 | J14: =SUM(C14:I14) -> 0
A15: F. | B15: METABOLIC ENDOCRINE SYSTEM (Diabetes, Hyperthyroidism, Hypothyroidism, Dyslipidemia) | C15: 3 | D15: 2 | E15: 0 | F15: 0 | G15: 0 | H15: 0 | I15: 1 | J15: =SUM(C15:I15) -> 6
A16: G. | B16: CARDIOVASCULAR SYSTEM (Chest pain, Hypertension, Hypotension, Arrhythmias, Bradycardia, Tachycardia) | C16: 3 | D16: 1 | E16: 0 | F16: 0 | G16: 1 | H16: 1 | I16: 0 | J16: =SUM(C16:I16) -> 6
A17: H. | B17: EYES, EARS, NOSE & THROAT DISORDERS (Sty, Fungal or Bacterial Infection, Foreign body,Vertigo, Otitis Media/Externa, Sinusitis, Epistaxis, Pharyngitis, Laryngitis, Tonsillitis, Rhinitis) | C17: 1 | D17: 0 | E17: 0 | F17: 1 | G17: 0 | H17: 1 | I17: 1 | J17: =SUM(C17:I17) -> 4
A18: I. | B18: COMMUNICABLE DISEASES (Conjunctivitis, Boils, Measles, Chicken Pox, Mumps, Hepatitis, Tuberculosis, Leptospirosis, COVID Suspect, Viral Exanthem | C18: 0 | D18: 0 | E18: 0 | F18: 0 | G18: 0 | H18: 0 | I18: 0 | J18: =SUM(C18:I18) -> 0
A19: J. | B19: BLOOD DISORDERS (Anemia, Pallor, ) | C19: 0 | D19: 0 | E19: 0 | F19: 0 | G19: 0 | H19: 0 | I19: 0 | J19: =SUM(C19:I19) -> 0
A20: K. | B20: NEUROLOGICAL DISORDERS (Hyperventilation, Anxiety attack, Panic Attack, Headache, Migraine, Syncope, Dizziness, Epilepsy, Seizure, Insomnia) | C20: 3 | D20: 0 | E20: 0 | F20: 0 | G20: 1 | H20: 0 | I20: 1 | J20: =SUM(C20:I20) -> 5
A21: L. | B21: OB-GYNE CASES (Dysmenorrhea, Pregnancy, Polycystic Ovarian Syndrome, Menstrual Disorders) | C21: 1 | D21: 1 | E21: 0 | F21: 1 | G21: 0 | H21: 0 | I21: 0 | J21: =SUM(C21:I21) -> 3
... A27: R. | B27: Heat related cases | C27: 10 | D27: 3 | E27: 1 | F27: 3 | G27: 1 | H27: 0 | I27: 0 | J27: =SUM(C27:I27) -> 18
B28: TOTAL | C28: =SUM(C10:C27) -> 46 | D28: =SUM(D10:D27) -> 15 | E28: =SUM(E10:E27) -> 4 | F28: =SUM(F10:F27) -> 6 | G28: =SUM(G10:G27) -> 6 | H28: =SUM(H10:H27) -> 5 | I28: =SUM(I10:I27) -> 7 | J28: =SUM(C28:I28) -> 89
A30: Prepared by:
A34: LORELEI P. DATU, RN
A35: Nurse I
A37: Noted by
A39: VICKY P. VITAL, EdD
A40: Director

Sheet June
A1: Republic of the Philippines
A2: DON HONORIO VENTURA STATE UNIVERSITY
A3: Villa de Bacolor, Pampanga
A4: Office of Student Welfare and Formation
A5: HEALTH SERVICES UNIT
A6: SUMMARY OF MEDICAL CASES
A7: June 2026
B9: CATEGORY | C9: College of Education (COE) | D9: College of Business Studies (CBS) | E9: College of Hospitality & Tourism Management | F9: College of Computing Studies | G9: College of Industrial Technology | H9: FACULTY | I9: NASA | J9: TOTAL
A10: A. | B10: ALIMENTARY SYSTEM (Nausea, Vomiting, Hyperacidty, Heartburn, Dyspepsia, Infectious Diarrhea, Constipation) | C10: 0 | D10: 0 | E10: 0 | F10: 0 | G10: 0 | H10: 0 | I10: 0 | J10: =SUM(C10:I10) -> 0
A11: B. | B11: RESPIRATORY SYSTEM (Cough, Colds, Fever, Bronchial Asthma, Difficulty of Breathing, Pneumonia) | C11: o | D11: 0 | E11: 0 | F11: 0 | G11: 0 | H11: 0 | I11: 3 | J11: =SUM(C11:I11) -> 3
A12: C. | B12: MUSCULO-SKELETAL SYSTEM (Osteoarthritis, Osteochondritis, Muscle and Joint Spasm, Sprain, Strain, Fracture, Dislocation) | C12: 0 | D12: 0 | E12: 0 | F12: 0 | G12: 0 | H12: 0 | I12: 0 | J12: =SUM(C12:I12) -> 0
A13: D. | B13: INTEGUMENTARY SYSTEM (Burns, Cuts, Abrasion, Laceration, Bruise, Puncture, Minor Surgery, Skin Diseases, Allergies, Infected Wound, Animal Bite) | C13: 0 | D13: 0 | E13: 0 | F13: 0 | G13: 0 | H13: 0 | I13: 0 | J13: =SUM(C13:I13) -> 0
A14: E. | B14: URINARY SYSTEM (UTI) | C14: o | D14: 0 | E14: 0 | F14: 0 | G14: 0 | H14: 0 | I14: 0 | J14: =SUM(C14:I14) -> 0
A15: F. | B15: METABOLIC ENDOCRINE SYSTEM (Diabetes, Hyperthyroidism, Hypothyroidism, Dyslipidemia) | C15: 0 | D15: 0 | E15: 0 | F15: 0 | G15: 0 | H15: 0 | I15: 0 | J15: =SUM(C15:I15) -> 0
A16: G. | B16: CARDIOVASCULAR SYSTEM (Chest pain, Hypertension, Hypotension, Arrhythmias, Bradycardia, Tachycardia) | C16: o | D16: 0 | E16: 0 | F16: 0 | G16: 0 | H16: 0 | I16: 0 | J16: =SUM(C16:I16) -> 0
A17: H. | B17: EYES, EARS, NOSE & THROAT DISORDERS (Sty, Fungal or Bacterial Infection, Foreign body,Vertigo, Otitis Media/Externa, Sinusitis, Epistaxis, Pharyngitis, Laryngitis, Tonsillitis, Rhinitis) | C17: 0 | D17: 0 | E17: 0 | F17: 0 | G17: 0 | H17: 0 | I17: 0 | J17: =SUM(C17:I17) -> 0
A18: I. | B18: COMMUNICABLE DISEASES (Conjunctivitis, Boils, Measles, Chicken Pox, Mumps, Hepatitis, Tuberculosis, Leptospirosis, COVID Suspect, Viral Exanthem | C18: 0 | D18: 0 | E18: 0 | F18: 0 | G18: 0 | H18: 0 | I18: 0 | J18: =SUM(C18:I18) -> 0
A19: J. | B19: BLOOD DISORDERS (Anemia, Pallor, ) | C19: 0 | D19: 0 | E19: 0 | F19: 0 | G19: 0 | H19: 0 | I19: 0 | J19: =SUM(C19:I19) -> 0
A20: K. | B20: NEUROLOGICAL DISORDERS (Hyperventilation, Anxiety attack, Panic Attack, Headache, Migraine, Syncope, Dizziness, Epilepsy, Seizure, Insomnia) | C20: 0 | D20: 0 | E20: 0 | F20: 0 | G20: 0 | H20: 0 | I20: 0 | J20: =SUM(C20:I20) -> 0
A21: L. | B21: OB-GYNE CASES (Dysmenorrhea, Pregnancy, Polycystic Ovarian Syndrome, Menstrual Disorders) | C21: 0 | D21: 0 | E21: 0 | F21: 0 | G21: 0 | H21: 0 | I21: 0 | J21: =SUM(C21:I21) -> 0
A22: M. | B22: DENTAL CASES | C22: 0 | D22: 0 | E22: 0 | F22: 0 | G22: 0 | H22: 0 | I22: 0 | J22: =SUM(C22:I22) -> 0
A23: N. | B23: PHYSICAL EXAMINATIONS (Medical Certificate/Clearance Issued) | C23: 0 | D23: 0 | E23: 0 | F23: 0 | G23: 241 | H23: 0 | I23: 0 | J23: =SUM(C23:I23) -> 241
A24: O. | B24: REFERRALS (Laboratory and Diagnostic Test Request, Specialist) | C24: 0 | D24: 0 | E24: 0 | F24: 0 | G24: 0 | H24: 0 | I24: 0 | J24: =SUM(C24:I24) -> 0
A25: P. | B25: FOLLOW - UP CHECK-UP | C25: 0 | D25: 0 | E25: 0 | F25: 0 | G25: 0 | H25: 0 | I25: 0 | J25: =SUM(C25:I25) -> 0
A26: Q. | B26: OTHERS (Height,Weight, Blood Pressure Monitoring, Prescription) | C26: 0 | D26: 0 | E26: 0 | F26: 0 | G26: 0 | H26: 0 | I26: 0 | J26: =SUM(C26:I26) -> 0
A27: R. | B27: Heat related cases | C27: 0 | D27: 0 | E27: 0 | F27: 0 | G27: 0 | H27: 0 | I27: 0 | J27: =SUM(C27:I27) -> 0
B28: TOTAL | C28: =SUM(C10:C27) -> 0 | D28: =SUM(D10:D27) -> 0 | E28: =SUM(E10:E27) -> 0 | F28: =SUM(F10:F27) -> 0 | G28: =SUM(G10:G27) -> 241 | H28: =SUM(H10:H27) -> 0 | I28: =SUM(I10:I27) -> 3 | J28: =SUM(C28:I28) -> 244
A30: Prepared by:
A32: LORELEI P. DATU
A33: Nurse I
A36: Noted by:
A38: VICKY P. VITAL, EdD
A39: Director

Sheet July
A1: Republic of the Philippines
A2: DON HONORIO VENTURA STATE UNIVERSITY
A3: Villa de Bacolor, Pampanga
A4: Office of Student Welfare and Formation
A5: HEALTH SERVICES UNIT
A6: SUMMARY OF MEDICAL CASES
A7: ________________ 2025
B9: CATEGORY | C9: College of Education (COE) | D9: College of Business Studies (CBS) | E9: College of Hospitality & Tourism Management | F9: College of Computing Studies | G9: College of Industrial Technology | H9: FACULTY | I9: NASA | J9: TOTAL
A10: A. | B10: ALIMENTARY SYSTEM (Nausea, Vomiting, Hyperacidty, Heartburn, Dyspepsia, Infectious Diarrhea, Constipation) | C10: 0 | D10: 0 | E10: 0 | F10: 0 | G10: 0 | H10: 1 | I10: 1 | J10: =SUM(C10:I10) -> 2
A11: B. | B11: RESPIRATORY SYSTEM (Cough, Colds, Fever, Bronchial Asthma, Difficulty of Breathing, Pneumonia) | C11: 0 | D11: 0 | E11: 0 | F11: 0 | G11: 0 | H11: 0 | I11: 0 | J11: =SUM(C11:I11) -> 0
A12: C. | B12: MUSCULO-SKELETAL SYSTEM (Osteoarthritis, Osteochondritis, Muscle and Joint Spasm, Sprain, Strain, Fracture, Dislocation) | C12: 0 | D12: 0 | E12: 0 | F12: 0 | G12: 0 | H12: 0 | I12: 0 | J12: =SUM(C12:I12) -> 0
A13: D. | B13: INTEGUMENTARY SYSTEM (Burns, Cuts, Abrasion, Laceration, Bruise, Puncture, Minor Surgery, Skin Diseases, Allergies, Infected Wound, Animal Bite) | C13: 0 | D13: 0 | E13: 0 | F13: 0 | G13: 0 | H13: 1 | I13: 0 | J13: =SUM(C13:I13) -> 1
A14: E. | B14: URINARY SYSTEM (UTI) | C14: 0 | D14: 0 | E14: 0 | F14: 0 | G14: 0 | H14: 0 | I14: 0 | J14: =SUM(C14:I14) -> 0
A15: F. | B15: METABOLIC ENDOCRINE SYSTEM (Diabetes, Hyperthyroidism, Hypothyroidism, Dyslipidemia) | C15: 0 | D15: 0 | E15: 0 | F15: 0 | G15: 0 | H15: 0 | I15: 0 | J15: =SUM(C15:I15) -> 0
A16: G. | B16: CARDIOVASCULAR SYSTEM (Chest pain, Hypertension, Hypotension, Arrhythmias, Bradycardia, Tachycardia) | C16: 0 | D16: 0 | E16: 0 | F16: 0 | G16: 0 | H16: 0 | I16: 1 | J16: =SUM(C16:I16) -> 1
A17: H. | B17: EYES, EARS, NOSE & THROAT DISORDERS (Sty, Fungal or Bacterial Infection, Foreign body,Vertigo, Otitis Media/Externa, Sinusitis, Epistaxis, Pharyngitis, Laryngitis, Tonsillitis, Rhinitis) | C17: 0 | D17: 0 | E17: 0 | F17: 0 | G17: 0 | H17: 0 | I17: 0 | J17: =SUM(C17:I17) -> 0
A18: I. | B18: COMMUNICABLE DISEASES (Conjunctivitis, Boils, Measles, Chicken Pox, Mumps, Hepatitis, Tuberculosis, Leptospirosis, COVID Suspect, Viral Exanthem | C18: 0 | D18: 0 | E18: 0 | F18: 0 | G18: 0 | H18: 0 | I18: 0 | J18: 0
A19: J. | B19: BLOOD DISORDERS (Anemia, Pallor, ) | C19: 0 | D19: 0 | E19: 0 | F19: 0 | G19: 0 | H19: 0 | I19: 0 | J19: =SUM(C19:I19) -> 0
A20: K. | B20: NEUROLOGICAL DISORDERS (Hyperventilation, Anxiety attack, Panic Attack, Headache, Migraine, Syncope, Dizziness, Epilepsy, Seizure, Insomnia) | C20: 0 | D20: 0 | E20: 0 | F20: 0 | G20: 0 | H20: 0 | I20: 0 | J20: =SUM(C20:I20) -> 0
A21: L. | B21: OB-GYNE CASES (Dysmenorrhea, Pregnancy, Polycystic Ovarian Syndrome, Menstrual Disorders) | C21: 0 | D21: 0 | E21: 0 | F21: 0 | G21: 0 | H21: 0 | I21: 0 | J21: =SUM(C21:I21) -> 0
A22: M. | B22: DENTAL CASES | C22: 0 | D22: 0 | E22: 0 | F22: 0 | G22: 0 | H22: 0 | I22: 0 | J22: =SUM(C22:I22) -> 0
A23: N. | B23: PHYSICAL EXAMINATIONS (Medical Certificate/Clearance Issued) | C23: 0 | D23: 0 | E23: 0 | F23: 0 | G23: 0 | H23: 0 | I23: 0 | J23: =SUM(C23:I23) -> 0
A24: O. | B24: REFERRALS (Laboratory and Diagnostic Test Request, Specialist) | C24: 0 | D24: 0 | E24: 0 | F24: 0 | G24: 0 | H24: 0 | I24: 0 | J24: =SUM(C24:I24) -> 0
A25: P. | B25: FOLLOW - UP CHECK-UP | C25: 0 | D25: 0 | E25: 0 | F25: 0 | G25: 0 | H25: 0 | I25: 0 | J25: =SUM(C25:I25) -> 0
A26: Q. | B26: OTHERS (Height,Weight, Blood Pressure Monitoring, Prescription) | C26: 0 | D26: 0 | E26: 0 | F26: 0 | G26: 0 | H26: 5 | I26: 1 | J26: =SUM(C26:I26) -> 6
A27: R. | B27: Heat related cases | C27: 0 | D27: 0 | E27: 0 | F27: 0 | G27: 0 | H27: 0 | I27: 0 | J27: =SUM(C27:I27) -> 0
B28: TOTAL | C28: =SUM(C10:C27) -> 0 | D28: =SUM(D10:D27) -> 0 | E28: =SUM(E10:E27) -> 0 | F28: =SUM(F10:F27) -> 0 | G28: =SUM(G10:G27) -> 0 | H28: =SUM(H10:H27) -> 7 | I28: =SUM(I10:I27) -> 3 | J28: =SUM(C28:I28) -> 10
A30: Prepared by:
A32: ________________________________________
A33: Nurse I
A36: Noted by:
A38: ________________________________________
A39: Director

Sheet August
A1: Republic of the Philippines
A2: PAMPANGA STATE UNIVERSITY
A3: (former Don Honorio Ventura State University)
A5: Mexico Campus
A6: SUMMARY OF MEDICAL CASES
A7: AUGUST 2025
B9: CATEGORY | C9: College of Education (COE) | D9: College of Business Studies (CBS) | E9: College of Hospitality & Tourism Management | F9: College of Computing Studies | G9: College of Industrial Technology | H9: FACULTY | I9: NASA | J9: TOTAL
A10: A. | B10: ALIMENTARY SYSTEM (Nausea, Vomiting, Hyperacidty, Heartburn, Dyspepsia, Infectious Diarrhea, Constipation) | C10: 5 | D10: 2 | E10: 0 | F10: 4 | G10: 0 | H10: 1 | I10: 1 | J10: =SUM(C10:I10) -> 13
A11: B. | B11: RESPIRATORY SYSTEM (Cough, Colds, Fever, Bronchial Asthma, Difficulty of Breathing, Pneumonia) | C11: 3 | D11: 0 | E11: 0 | F11: 2 | G11: 3 | H11: 1 | I11: 1 | J11: =SUM(C11:I11) -> 10
A12: C. | B12: MUSCULO-SKELETAL SYSTEM (Osteoarthritis, Osteochondritis, Muscle and Joint Spasm, Sprain, Strain, Fracture, Dislocation) | C12: 1 | D12: 1 | E12: 0 | F12: 0 | G12: 0 | H12: 0 | I12: 0 | J12: =SUM(C12:I12) -> 2
A13: D. | B13: INTEGUMENTARY SYSTEM (Burns, Cuts, Abrasion, Laceration, Bruise, Puncture, Minor Surgery, Skin Diseases, Allergies, Infected Wound, Animal Bite) | C13: 0 | D13: 1 | E13: 3 | F13: 0 | G13: 0 | H13: 0 | I13: 1 | J13: =SUM(C13:I13) -> 5
A14: E. | B14: URINARY SYSTEM (UTI) | C14: 0 | D14: 0 | E14: 0 | F14: 0 | G14: 0 | H14: 0 | I14: 0 | J14: =SUM(C14:I14) -> 0
A15: F. | B15: METABOLIC ENDOCRINE SYSTEM (Diabetes, Hyperthyroidism, Hypothyroidism, Dyslipidemia) | C15: 0 | D15: 0 | E15: 0 | F15: 0 | G15: 0 | H15: 0 | I15: 0 | J15: =SUM(C15:I15) -> 0
A16: G. | B16: CARDIOVASCULAR SYSTEM (Chest pain, Hypertension, Hypotension, Arrhythmias, Bradycardia, Tachycardia) | C16: 0 | D16: 1 | E16: 0 | F16: 0 | G16: 0 | H16: 0 | I16: 0 | J16: =SUM(C16:I16) -> 1
A17: H. | B17: EYES, EARS, NOSE & THROAT DISORDERS (Sty, Fungal or Bacterial Infection, Foreign body,Vertigo, Otitis Media/Externa, Sinusitis, Epistaxis, Pharyngitis, Laryngitis, Tonsillitis, Rhinitis) | C17: 1 | D17: 0 | E17: 0 | F17: 0 | G17: 0 | H17: 0 | I17: 0 | J17: =SUM(C17:I17) -> 1
A18: I. | B18: COMMUNICABLE DISEASES (Conjunctivitis, Boils, Measles, Chicken Pox, Mumps, Hepatitis, Tuberculosis, Leptospirosis, COVID Suspect, Viral Exanthem | C18: 0 | D18: 0 | E18: 0 | F18: 0 | G18: 0 | H18: 0 | I18: 0 | J18: =SUM(C18:I18) -> 0
A19: J. | B19: BLOOD DISORDERS (Anemia, Pallor, ) | C19: 0 | D19: 0 | E19: 0 | F19: 0 | G19: 0 | H19: 0 | I19: 0 | J19: =SUM(C19:I19) -> 0
A20: K. | B20: NEUROLOGICAL DISORDERS (Hyperventilation, Anxiety attack, Panic Attack, Headache, Migraine, Syncope, Dizziness, Epilepsy, Seizure, Insomnia) | C20: 1 | D20: 5 | E20: 0 | F20: 2 | G20: 0 | H20: 0 | I20: 0 | J20: =SUM(C20:I20) -> 8
A21: L. | B21: OB-GYNE CASES (Dysmenorrhea, Pregnancy, Polycystic Ovarian Syndrome, Menstrual Disorders) | C21: 1 | D21: 1 | E21: 0 | F21: 0 | G21: 0 | H21: 0 | I21: 1 | J21: =SUM(C21:I21) -> 3
... A26: Q. | B26: OTHERS (Height,Weight, Blood Pressure Monitoring, Prescription) | C26: 0 | D26: 0 | E26: 0 | F26: 0 | G26: 0 | H26: 3 | I26: 0 | J26: =SUM(C26:I26) -> 3
A27: R. | B27: Heat related cases | C27: 1 | D27: 1 | E27: 1 | F27: 0 | G27: 0 | H27: 0 | J27: =SUM(C27:I27) -> 3
B28: TOTAL | C28: =SUM(C10:C27) -> 49 | D28: =C2+SUM(D10:D27) -> 12 | E28: =SUM(E10:E27) -> 4 | F28: =SUM(F10:F27) -> 8 | G28: =SUM(G10:G27) -> 3 | H28: =SUM(H10:H27) -> 5 | I28: =SUM(I10:I27) -> 4 | J28: =SUM(C28:I28) -> 85
A30: Prepared by:
A32: LORELEI P. DATU, RN_______________________________________
A33: Nurse I
A36: Noted by:
A38: VICKY P. VITAL, EdD
A39: Director

Sheet September
A1: Republic of the Philippines
A2: PAMPANGA STATE UNIVERSITY
A3: (former Don Honorio Ventura State University)
A5: Mexico Campus
B6: HEALTH SERVICES
A7: SUMMARY OF MEDICAL CASES
A8: SEPTEMBER 2025
B10: CATEGORY | C10: College of Education (COE) | D10: College of Business Studies (CBS) | E10: College of Hospitality & Tourism Management | F10: College of Computing Studies | G10: College of Industrial Technology | H10: FACULTY | I10: NASA | J10: TOTAL
A11: A. | B11: ALIMENTARY SYSTEM (Nausea, Vomiting, Hyperacidty, Heartburn, Dyspepsia, Infectious Diarrhea, Constipation) | C11: 9 | D11: 6 | E11: 0 | F11: 4 | G11: 5 | H11: 0 | I11: 2 | J11: =SUM(C11:I11) -> 26
A12: B. | B12: RESPIRATORY SYSTEM (Cough, Colds, Fever, Bronchial Asthma, Difficulty of Breathing, Pneumonia) | C12: 12 | D12: 6 | E12: 6 | F12: 3 | G12: 5 | H12: 2 | I12: 8 | J12: =SUM(C12:I12) -> 42
A13: C. | B13: MUSCULO-SKELETAL SYSTEM (Osteoarthritis, Osteochondritis, Muscle and Joint Spasm, Sprain, Strain, Fracture, Dislocation) | C13: 2 | D13: 1 | E13: 6 | F13: 0 | G13: 0 | H13: 0 | I13: 3 | J13: =SUM(C13:I13) -> 12
A14: D. | B14: INTEGUMENTARY SYSTEM (Burns, Cuts, Abrasion, Laceration, Bruise, Puncture, Minor Surgery, Skin Diseases, Allergies, Infected Wound, Animal Bite) | C14: 5 | D14: 1 | E14: 6 | F14: 0 | G14: 2 | H14: 0 | I14: 3 | J14: =SUM(C14:I14) -> 17
A15: E. | B15: URINARY SYSTEM (UTI) | C15: 0 | D15: 0 | E15: 0 | F15: 0 | G15: 1 | H15: 0 | I15: 0 | J15: =SUM(C15:I15) -> 1
A16: F. | B16: METABOLIC ENDOCRINE SYSTEM (Diabetes, Hyperthyroidism, Hypothyroidism, Dyslipidemia) | C16: 0 | D16: 0 | E16: 0 | F16: 0 | G16: 0 | H16: 0 | I16: 0 | J16: =SUM(C16:I16) -> 0
A17: G. | B17: CARDIOVASCULAR SYSTEM (Chest pain, Hypertension, Hypotension, Arrhythmias, Bradycardia, Tachycardia) | C17: 2 | D17: 2 | E17: 0 | F17: 0 | G17: 1 | H17: 0 | I17: 0 | J17: =SUM(C17:I17) -> 5
A18: H. | B18: EYES, EARS, NOSE & THROAT DISORDERS (Sty, Fungal or Bacterial Infection, Foreign body,Vertigo, Otitis Media/Externa, Sinusitis, Epistaxis, Pharyngitis, Laryngitis, Tonsillitis, Rhinitis) | C18: 0 | D18: 0 | E18: 0 | F18: 0 | G18: 0 | H18: 0 | I18: 0 | J18: =SUM(C18:I18) -> 0
A19: I. | B19: COMMUNICABLE DISEASES (Conjunctivitis, Boils, Measles, Chicken Pox, Mumps, Hepatitis, Tuberculosis, Leptospirosis, COVID Suspect, Viral Exanthem | C19: 0 | D19: 0 | E19: 0 | F19: 0 | G19: 0 | H19: 0 | I19: 0 | J19: =SUM(C19:I19) -> 0
A20: J. | B20: BLOOD DISORDERS (Anemia, Pallor, ) | C20: 0 | D20: 0 | E20: 0 | F20: 0 | G20: 0 | H20: 0 | I20: 0 | J20: =SUM(C20:I20) -> 0
A21: K. | B21: NEUROLOGICAL DISORDERS (Hyperventilation, Anxiety attack, Panic Attack, Headache, Migraine, Syncope, Dizziness, Epilepsy, Seizure, Insomnia) | C21: 5 | D21: 3 | E21: 3 | F21: 1 | G21: 0 | H21: 0 | I21: 0 | J21: =SUM(C21:I21) -> 12
A22: L. | B22: OB-GYNE CASES (Dysmenorrhea, Pregnancy, Polycystic Ovarian Syndrome, Menstrual Disorders) | C22: 5 | D22: 2 | E22: 0 | F22: 0 | G22: 0 | H22: 0 | I22: 0 | J22: =SUM(C22:I22) -> 7
... A28: R. | B28: Heat related cases | C28: 0 | D28: 2 | E28: 0 | F28: 0 | G28: 0 | H28: 0 | I28: 0 | J28: =SUM(C28:I28) -> 2
B29: TOTAL | C29: =SUM(C11:C28) -> 227 | D29: =SUM(D11:D28) -> 23 | E29: =SUM(E11:E28) -> 21 | F29: =SUM(F11:F28) -> 8 | G29: =SUM(G11:G28) -> 15 | H29: =SUM(H11:H28) -> 2 | I29: =SUM(I11:I28) -> 16 | J29: =SUM(C29:I29) -> 312
A31: Prepared by:
A33: LORELEI P. DATU, RN
A34: Nurse I
B36: #VALUE!
A37: Noted by:
A39: VICKY P. VITAL, EdD
A40: Director

Sheet October
A1: Republic of the Philippines
A2: PAMPANGA STATE UNIVERSITY
A3: (former Don Honorio Ventura State University)
A5: Mexico Campus
A7: SUMMARY OF MEDICAL CASES
A8: October 2025
B10: CATEGORY | C10: College of Education (COE) | D10: College of Business Studies (CBS) | E10: College of Hospitality & Tourism Management | F10: College of Computing Studies | G10: College of Industrial Technology | H10: FACULTY | I10: NASA | J10: TOTAL
A11: A. | B11: ALIMENTARY SYSTEM (Nausea, Vomiting, Hyperacidty, Heartburn, Dyspepsia, Infectious Diarrhea, Constipation) | C11: 12 | D11: 3 | E11: 3 | F11: 3 | G11: 3 | H11: 1 | I11: 1 | J11: =SUM(C11:I11) -> 26
A12: B. | B12: RESPIRATORY SYSTEM (Cough, Colds, Fever, Bronchial Asthma, Difficulty of Breathing, Pneumonia) | C12: 20 | D12: 8 | E12: 6 | F12: 4 | G12: 9 | H12: 3 | I12: 5 | J12: =SUM(C12:I12) -> 55
A13: C. | B13: MUSCULO-SKELETAL SYSTEM (Osteoarthritis, Osteochondritis, Muscle and Joint Spasm, Sprain, Strain, Fracture, Dislocation) | C13: 5 | D13: 1 | E13: 1 | F13: 0 | G13: 0 | H13: 0 | I13: 1 | J13: =SUM(C13:I13) -> 8
A14: D. | B14: INTEGUMENTARY SYSTEM (Burns, Cuts, Abrasion, Laceration, Bruise, Puncture, Minor Surgery, Skin Diseases, Allergies, Infected Wound, Animal Bite) | C14: 4 | D14: 6 | E14: 3 | F14: 6 | G14: 0 | H14: 2 | I14: 0 | J14: =SUM(C14:I14) -> 21
A15: E. | B15: URINARY SYSTEM (UTI) | C15: 0 | D15: 0 | E15: 1 | F15: 0 | G15: 0 | H15: 0 | I15: 0 | J15: =SUM(C15:I15) -> 1
A16: F. | B16: METABOLIC ENDOCRINE SYSTEM (Diabetes, Hyperthyroidism, Hypothyroidism, Dyslipidemia) | C16: 0 | D16: 0 | E16: 0 | F16: 0 | G16: 0 | H16: 0 | I16: 0 | J16: =SUM(C16:I16) -> 0
A17: G. | B17: CARDIOVASCULAR SYSTEM (Chest pain, Hypertension, Hypotension, Arrhythmias, Bradycardia, Tachycardia) | C17: 2 | D17: 9 | E17: 1 | F17: 0 | G17: 0 | H17: 0 | I17: 0 | J17: =SUM(C17:I17) -> 12
A18: H. | B18: EYES, EARS, NOSE & THROAT DISORDERS (Sty, Fungal or Bacterial Infection, Foreign body,Vertigo, Otitis Media/Externa, Sinusitis, Epistaxis, Pharyngitis, Laryngitis, Tonsillitis, Rhinitis) | C18: 0 | D18: 0 | E18: 0 | F18: 0 | G18: 1 | H18: 0 | I18: 0 | J18: =SUM(C18:I18) -> 1
A19: I. | B19: COMMUNICABLE DISEASES (Conjunctivitis, Boils, Measles, Chicken Pox, Mumps, Hepatitis, Tuberculosis, Leptospirosis, COVID Suspect, Viral Exanthem | C19: 0 | D19: 0 | E19: 0 | F19: 0 | G19: 0 | H19: 0 | I19: 0 | J19: =SUM(C19:I19) -> 0
A20: J. | B20: BLOOD DISORDERS (Anemia, Pallor, ) | C20: 0 | D20: 0 | E20: 1 | F20: 0 | G20: 0 | H20: 0 | I20: 0 | J20: =SUM(C20:I20) -> 1
A21: K. | B21: NEUROLOGICAL DISORDERS (Hyperventilation, Anxiety attack, Panic Attack, Headache, Migraine, Syncope, Dizziness, Epilepsy, Seizure, Insomnia) | C21: 9 | D21: 0 | E21: 5 | F21: 0 | G21: 0 | H21: 0 | I21: 0 | J21: =SUM(C21:I21) -> 14
A22: L. | B22: OB-GYNE CASES (Dysmenorrhea, Pregnancy, Polycystic Ovarian Syndrome, Menstrual Disorders) | C22: 5 | D22: 0 | E22: 1 | F22: 0 | G22: 0 | H22: 0 | I22: 0 | J22: =SUM(C22:I22) -> 6
A23: M. | B23: DENTAL CASES | C23: 0 | D23: 3 | E23: 0 | F23: 0 | G23: 0 | H23: 0 | I23: 0 | J23: =SUM(C23:I23) -> 3
A24: N. | B24: PHYSICAL EXAMINATIONS (Medical Certificate/Clearance Issued) | C24: 1 | D24: 0 | E24: 0 | F24: 0 | G24: 3 | H24: 0 | I24: 0 | J24: 0 | K24: 0
A25: O. | B25: REFERRALS (Laboratory and Diagnostic Test Request, Specialist) | C25: 0 | D25: 0 | E25: 0 | F25: 0 | G25: 0 | H25: 0 | I25: 0 | J25: =SUM(C25:I25) -> 0
A26: P. | B26: FOLLOW - UP CHECK-UP | C26: 0 | D26: 0 | E26: 0 | F26: 0 | G26: 0 | H26: 0 | I26: 0 | J26: =SUM(C26:I26) -> 0
A27: Q. | B27: OTHERS (Height,Weight, Blood Pressure Monitoring, Prescription) | C27: 0 | D27: 1 | E27: 0 | F27: 0 | G27: 0 | H27: 0 | I27: 0 | J27: =SUM(C27:I27) -> 1
A28: R. | B28: Heat related cases | C28: 0 | D28: 0 | E28: 1 | F28: 0 | G28: 0 | H28: 0 | I28: 0 | J28: =SUM(C28:I28) -> 1
B29: TOTAL | C29: =SUM(C11:C28) -> 58 | D29: =SUM(D11:D28) -> 31 | E29: =SUM(E11:E28) -> 23 | F29: =SUM(F11:F28) -> 13 | G29: =SUM(G11:G28) -> 16 | H29: =SUM(H11:H28) -> 6 | I29: =SUM(I11:I28) -> 7 | J29: =SUM(C29:I29) -> 154
A31: Prepared by:
A33: LORELEI P. DATU, RN
A34: Nurse I
A37: Noted by:
A39: VICKY P.VITAL, EdD
A40: Director

Sheet November
A2: Republic of the Philippines
A3: PAMPANGA STATE UNIVERSITY
A4: (former Don Honorio Ventura State University)
A6: Mexico Campus
B7: HEALTH SERVICES
A8: SUMMARY OF MEDICAL CASES
A9: November 2025
B10: CATEGORY | C10: College of Education (COE) | D10: College of Business Studies (CBS) | E10: College of Hospitality & Tourism Management | F10: College of Computing Studies | G10: College of Industrial Technology | H10: FACULTY | I10: NASA | J10: TOTAL
A11: A. | B11: ALIMENTARY SYSTEM (Nausea, Vomiting, Hyperacidty, Heartburn, Dyspepsia, Infectious Diarrhea, Constipation) | C11: 4 | D11: 1 | E11: 0 | F11: 2 | G11: 1 | H11: 2 | I11: 0 | J11: =SUM(C11:I11) -> 10
A12: B. | B12: RESPIRATORY SYSTEM (Cough, Colds, Fever, Bronchial Asthma, Difficulty of Breathing, Pneumonia) | C12: 6 | D12: 3 | E12: 2 | F12: 3 | G12: 0 | H12: 0 | I12: 1 | J12: =SUM(C12:I12) -> 15
A13: C. | B13: MUSCULO-SKELETAL SYSTEM (Osteoarthritis, Osteochondritis, Muscle and Joint Spasm, Sprain, Strain, Fracture, Dislocation) | C13: 0 | D13: 2 | E13: 0 | F13: 0 | G13: 0 | H13: 0 | I13: 0 | J13: =SUM(C13:I13) -> 2
A14: D. | B14: INTEGUMENTARY SYSTEM (Burns, Cuts, Abrasion, Laceration, Bruise, Puncture, Minor Surgery, Skin Diseases, Allergies, Infected Wound, Animal Bite) | C14: 0 | D14: 0 | E14: 0 | F14: 0 | G14: 0 | H14: 0 | I14: 0 | J14: =SUM(C14:I14) -> 0
A15: E. | B15: URINARY SYSTEM (UTI) | C15: 0 | D15: 0 | E15: 0 | F15: 0 | G15: 0 | H15: 0 | I15: 0 | J15: =SUM(C15:I15) -> 0
A16: F. | B16: METABOLIC ENDOCRINE SYSTEM (Diabetes, Hyperthyroidism, Hypothyroidism, Dyslipidemia) | C16: 0 | D16: 0 | E16: 0 | F16: 0 | G16: 0 | H16: 0 | I16: 0 | J16: =SUM(C16:I16) -> 0
A17: G. | B17: CARDIOVASCULAR SYSTEM (Chest pain, Hypertension, Hypotension, Arrhythmias, Bradycardia, Tachycardia) | C17: 2 | D17: 1 | E17: 0 | F17: 0 | G17: 0 | H17: 0 | I17: 0 | J17: =SUM(C17:I17) -> 3
A18: H. | B18: EYES, EARS, NOSE & THROAT DISORDERS (Sty, Fungal or Bacterial Infection, Foreign body,Vertigo, Otitis Media/Externa, Sinusitis, Epistaxis, Pharyngitis, Laryngitis, Tonsillitis, Rhinitis) | C18: 0 | D18: 1 | E18: 0 | F18: 0 | G18: 0 | H18: 0 | I18: 0 | J18: =SUM(C18:I18) -> 1
A19: I. | B19: COMMUNICABLE DISEASES (Conjunctivitis, Boils, Measles, Chicken Pox, Mumps, Hepatitis, Tuberculosis, Leptospirosis, COVID Suspect, Viral Exanthem | C19: 0 | D19: 0 | E19: 0 | F19: 0 | G19: 0 | H19: 0 | I19: 0 | J19: =SUM(C19:I19) -> 0
A20: J. | B20: BLOOD DISORDERS (Anemia, Pallor, ) | C20: 0 | D20: 0 | E20: 0 | F20: 0 | G20: 0 | H20: 0 | I20: 0 | J20: =SUM(C20:I20) -> 0
A21: K. | B21: NEUROLOGICAL DISORDERS (Hyperventilation, Anxiety attack, Panic Attack, Headache, Migraine, Syncope, Dizziness, Epilepsy, Seizure, Insomnia) | C21: 7 | D21: 5 | E21: 2 | F21: 0 | G21: 0 | H21: 0 | I21: 0 | J21: =SUM(C21:I21) -> 14
A22: L. | B22: OB-GYNE CASES (Dysmenorrhea, Pregnancy, Polycystic Ovarian Syndrome, Menstrual Disorders) | C22: 0 | D22: 0 | E22: 0 | F22: 0 | G22: 0 | H22: 0 | I22: 0 | J22: =SUM(C22:I22) -> 0
... A28: R. | B28: Heat related cases | C28: 0 | D28: 0 | E28: 0 | F28: 0 | G28: 0 | H28: 0 | I28: 0 | J28: =SUM(C28:I28) -> 0
B29: TOTAL | C29: =SUM(C11:C28) -> 19 | D29: =SUM(D11:D28) -> 13 | E29: =SUM(E11:E28) -> 4 | F29: =SUM(F11:F28) -> 5 | G29: =SUM(G11:G28) -> 1 | H29: =SUM(H11:H28) -> 2 | I29: =SUM(I11:I28) -> 1 | J29: =SUM(C29:I29) -> 45
A31: Prepared by:
A33: ________________________________________ | B33: LORELEI P. DATU
A34: Nurse I
A37: Noted by:
A39: VICKY P. VITAL, EdD
A40: Director

Sheet December
A1: Republic of the Philippines
A2: PAMPANGA STATE UNIVERSITY
A3: (former Don Honorio Ventura State University)
A5: Mexico Campus
B6: HEALTH SERVICES
A7: SUMMARY OF MEDICAL CASES
A8: DECEMBER 2025
B10: CATEGORY | C10: College of Education (COE) | D10: College of Business Studies (CBS) | E10: College of Hospitality & Tourism Management | F10: College of Computing Studies | G10: College of Industrial Technology | H10: FACULTY | I10: NASA | J10: TOTAL
A11: A. | B11: ALIMENTARY SYSTEM (Nausea, Vomiting, Hyperacidty, Heartburn, Dyspepsia, Infectious Diarrhea, Constipation) | C11: 4 | D11: 5 | E11: 2 | F11: 0 | G11: 1 | H11: 0 | I11: 0 | J11: =SUM(C11:I11) -> 12
A12: B. | B12: RESPIRATORY SYSTEM (Cough, Colds, Fever, Bronchial Asthma, Difficulty of Breathing, Pneumonia) | C12: 8 | D12: 3 | E12: 2 | F12: 0 | G12: 6 | H12: 3 | I12: 3 | J12: =SUM(C12:I12) -> 25
A13: C. | B13: MUSCULO-SKELETAL SYSTEM (Osteoarthritis, Osteochondritis, Muscle and Joint Spasm, Sprain, Strain, Fracture, Dislocation) | C13: 0 | D13: 0 | E13: 1 | F13: 0 | G13: 1 | H13: 0 | I13: 1 | J13: =SUM(C13:I13) -> 3
A14: D. | B14: INTEGUMENTARY SYSTEM (Burns, Cuts, Abrasion, Laceration, Bruise, Puncture, Minor Surgery, Skin Diseases, Allergies, Infected Wound, Animal Bite) | C14: 3 | D14: 1 | E14: 1 | F14: 0 | G14: 0 | H14: 0 | I14: 1 | J14: =SUM(C14:I14) -> 6
A15: E. | B15: URINARY SYSTEM (UTI) | C15: 0 | D15: 0 | E15: 0 | F15: 0 | G15: 0 | H15: 0 | I15: 0 | J15: =SUM(C15:I15) -> 0
A16: F. | B16: METABOLIC ENDOCRINE SYSTEM (Diabetes, Hyperthyroidism, Hypothyroidism, Dyslipidemia) | C16: 0 | D16: 0 | E16: 0 | F16: 0 | G16: 0 | H16: 0 | I16: 0 | J16: =SUM(C16:I16) -> 0
A17: G. | B17: CARDIOVASCULAR SYSTEM (Chest pain, Hypertension, Hypotension, Arrhythmias, Bradycardia, Tachycardia) | C17: 4 | D17: 0 | E17: 0 | F17: 0 | G17: 0 | H17: 0 | I17: 0 | J17: =SUM(C17:I17) -> 4
A18: H. | B18: EYES, EARS, NOSE & THROAT DISORDERS (Sty, Fungal or Bacterial Infection, Foreign body,Vertigo, Otitis Media/Externa, Sinusitis, Epistaxis, Pharyngitis, Laryngitis, Tonsillitis, Rhinitis) | C18: 0 | D18: 0 | E18: 0 | F18: 0 | G18: 0 | H18: 0 | I18: 0 | J18: =SUM(C18:I18) -> 0
A19: I. | B19: COMMUNICABLE DISEASES (Conjunctivitis, Boils, Measles, Chicken Pox, Mumps, Hepatitis, Tuberculosis, Leptospirosis, COVID Suspect, Viral Exanthem | C19: 0 | D19: 0 | E19: 0 | F19: 0 | G19: 1 | H19: 0 | I19: 0 | J19: =SUM(C19:I19) -> 1
A20: J. | B20: BLOOD DISORDERS (Anemia, Pallor, ) | C20: 0 | D20: 0 | E20: 0 | F20: 0 | G20: 0 | H20: 0 | I20: 0 | J20: =SUM(C20:I20) -> 0
A21: K. | B21: NEUROLOGICAL DISORDERS (Hyperventilation, Anxiety attack, Panic Attack, Headache, Migraine, Syncope, Dizziness, Epilepsy, Seizure, Insomnia) | C21: 4 | D21: 0 | E21: 1 | F21: 0 | G21: 1 | H21: 0 | I21: 0 | J21: =SUM(C21:I21) -> 6
A22: L. | B22: OB-GYNE CASES (Dysmenorrhea, Pregnancy, Polycystic Ovarian Syndrome, Menstrual Disorders) | C22: 1 | D22: 0 | E22: 0 | F22: 0 | G22: 0 | H22: 0 | I22: 0 | J22: =SUM(C22:I22) -> 1
... A28: R. | B28: Heat related cases | C28: 0 | D28: 0 | E28: 0 | F28: 0 | G28: 0 | H28: 0 | I28: 0 | J28: =SUM(C28:I28) -> 0
B29: TOTAL | C29: =SUM(C11:C28) -> 25 | D29: =SUM(D11:D28) -> 9 | E29: =SUM(E11:E28) -> 7 | F29: =SUM(F11:F28) -> 0 | G29: =SUM(G11:G28) -> 11 | H29: =SUM(H11:H28) -> 4 | I29: =SUM(I11:I28) -> 6 | J29: =SUM(C29:I29) -> 62
A31: Prepared by:
A33: LORELEI P. DATU,RN
A34: Nurse I
A37: Noted by:
A39: ________________________________________ | B39: VICKY P. VITAL, EdD
A40: Director

Sheet CONSOLIDATED-DO NOT EDIT 
A1: Republic of the Philippines
A2: PAMPANGA STATE UNIVERSITY
A3: (former Don Honorio Ventura State University)
A5: Mexico Campus
B6: HEALTH SERVICES
A7: SUMMARY OF MEDICAL CASES
A8: JANUARY TO DEC, 2025
B10: CATEGORY | C10: College of Education (COE) | D10: College of Business Studies (CBS) | E10: College of Hospitality & Tourism Management | F10: College of Computing Studies | G10: College of Industrial Technology | H10: FACULTY | I10: NASA | J10: TOTAL
A11: A. | B11: ALIMENTARY SYSTEM (Nausea, Vomiting, Hyperacidty, Heartburn, Dyspepsia, Infectious Diarrhea, Constipation) | C11: =SUM(January!C11,February!C11,March!C11,April!C11,May!C11,June!C11,July!C11,August!C11,September!C11,October!C11,November!C11,December!C11) -> 63 | D11: =SUM(January!D11,February!D11,March!D11,April!D11,May!D11,June!D11,July!D11,August!D11,September!D11,October!D11,November!D11,December!D11) -> 34 | E11: =SUM(January!E11,February!E11,March!E11,April!E11,May!E11,June!E11,July!E11,August!E11,September!E11,October!E11,November!E11,December!E11) -> 5 | F11: =SUM(January!F11,February!F11,March!F11,April!F11,May!F11,June!F11,July!F11,August!F11,September!F11,October!F11,November!F11,December!F11) -> 21 | G11: =SUM(January!G11,February!G11,March!G11,April!G11,May!G11,June!G11,July!G11,August!G11,September!G11,October!G11,November!G11,December!G11) -> 25 | H11: =SUM(January!H11,February!H11,March!H11,April!H11,May!H11,June!H11,July!H11,August!H11,September!H11,October!H11,November!H11,December!H11) -> 15 | I11: =SUM(January!I11,February!I11,March!I11,April!I11,May!I11,June!I11,July!I11,August!I11,September!I11,October!I11,November!I11,December!I11) -> 17 | J11: =SUM(C11:I11) -> 180
A12: B. | B12: RESPIRATORY SYSTEM (Cough, Colds, Fever, Bronchial Asthma, Difficulty of Breathing, Pneumonia) | C12: =SUM(January!C12,February!C12,March!C12,April!C12,May!C12,June!C12,July!C12,August!C12,September!C12,October!C12,November!C12,December!C12) -> 54 | D12: =SUM(January!D12,February!D12,March!D12,April!D12,May!D12,June!D12,July!D12,August!D12,September!D12,October!D12,November!D12,December!D12) -> 23 | E12: =SUM(January!E12,February!E12,March!E12,April!E12,May!E12,June!E12,July!E12,August!E12,September!E12,October!E12,November!E12,December!E12) -> 16 | F12: =SUM(January!F12,February!F12,March!F12,April!F12,May!F12,June!F12,July!F12,August!F12,September!F12,October!F12,November!F12,December!F12) -> 13 | G12: =SUM(January!G12,February!G12,March!G12,April!G12,May!G12,June!G12,July!G12,August!G12,September!G12,October!G12,November!G12,December!G12) -> 21 | H12: =SUM(January!H12,February!H12,March!H12,April!H12,May!H12,June!H12,July!H12,August!H12,September!H12,October!H12,November!H12,December!H12) -> 8 | I12: =SUM(January!I12,February!I12,March!I12,April!I12,May!I12,June!I12,July!I12,August!I12,September!I12,October!I12,November!I12,December!I12) -> 19 | J12: =SUM(C12:I12) -> 154
A13: C. | B13: MUSCULO-SKELETAL SYSTEM (Osteoarthritis, Osteochondritis, Muscle and Joint Spasm, Sprain, Strain, Fracture, Dislocation) | C13: =SUM(January!C13,February!C13,March!C13,April!C13,May!C13,June!C13,July!C123,August!C13,September!C13,October!C13,November!C13,December!C13) -> 19 | D13: =SUM(January!D12,February!D12,March!D12,April!D12,May!D12,June!D12,July!D12,August!D12,September!D13,October!D13,November!D13,December!D13) -> 7 | E13: =SUM(January!E12,February!E12,March!E12,April!E12,May!E12,June!E12,July!E12,August!E12,September!E13,October!E13,November!E13,December!E13) -> 8 | F13: =SUM(January!F12,February!F12,March!F12,April!F12,May!F12,June!F12,July!F12,August!F12,September!F13,October!F13,November!F13,December!F13) -> 3 | G13: =SUM(January!G12,February!G12,March!G12,April!G12,May!G12,June!G12,July!G12,August!G12,September!G13,October!G13,November!G13,December!G13) -> 2 | H13: =SUM(January!H12,February!H12,March!H12,April!H12,May!H12,June!H12,July!H12,August!H12,September!H13,October!H13,November!H13,December!H13) -> 0 | I13: =SUM(January!I12,February!I12,March!I12,April!I12,May!I12,June!I12,July!I12,August!I12,September!I13,October!I13,November!I13,December!I13) -> 7 | J13: =SUM(C13:I13) -> 46
A14: D. | B14: INTEGUMENTARY SYSTEM (Burns, Cuts, Abrasion, Laceration, Bruise, Puncture, Minor Surgery, Skin Diseases, Allergies, Infected Wound, Animal Bite) | C14: =SUM(January!C14,February!C14,March!C14,April!C14,May!C14,June!C14,July!C14,August!C14,September!C14,October!C14,November!C14,December!C14) -> 14 | D14: =SUM(January!D13,February!D13,March!D13,April!D13,May!D13,June!D13,July!D13,August!D13,September!D14,October!D14,November!D14,December!D14) -> 14 | E14: =SUM(January!E13,February!E13,March!E13,April!E13,May!E13,June!E13,July!E13,August!E13,September!E14,October!E14,November!E14,December!E14) -> 14 | F14: =SUM(January!F13,February!F13,March!F13,April!F13,May!F13,June!F13,July!F13,August!F13,September!F14,October!F14,November!F14,December!F14) -> 7 | G14: =SUM(January!G13,February!G13,March!G13,April!G13,May!G13,June!G13,July!G13,August!G13,September!G14,October!G14,November!G14,December!G14) -> 5 | H14: =SUM(January!H13,February!H13,March!H13,April!H13,May!H13,June!H13,July!H13,August!H13,September!H14,October!H14,November!H14,December!H14) -> 3 | I14: =SUM(January!I13,February!I13,March!I13,April!I13,May!I13,June!I13,July!I13,August!I13,September!I14,October!I14,November!I14,December!I14) -> 5 | J14: =SUM(C14:I14) -> 62
A15: E. | B15: URINARY SYSTEM (UTI) | C15: =SUM(January!C15,February!C15,March!C15,April!C15,May!C15,June!C15,July!C15,August!C14,September!C15,October!C15,November!C15,December!C15) -> 3 | D15: =SUM(January!D14,February!D14,March!D14,April!D14,May!D14,June!D14,July!D14,August!D14,September!D15,October!D15,November!D15,December!D15) -> 0 | E15: =SUM(January!E14,February!E14,March!E14,April!E14,May!E14,June!E14,July!E14,August!E14,September!E15,October!E15,November!E15,December!E15) -> 1 | F15: =SUM(January!F14,February!F14,March!F14,April!F14,May!F14,June!F14,July!F14,August!F14,September!F15,October!F15,November!F15,December!F15) -> 0 | G15: =SUM(January!G14,February!G14,March!G14,April!G14,May!G14,June!G14,July!G14,August!G14,September!G15,October!G15,November!G15,December!G15) -> 2 | H15: =SUM(January!H14,February!H14,March!H14,April!H14,May!H14,June!H14,July!H14,August!H14,September!H15,October!H15,November!H15,December!H15) -> 0 | I15: =SUM(January!I14,February!I14,March!I14,April!I14,May!I14,June!I14,July!I14,August!I14,September!I15,October!I15,November!I15,December!I15) -> 3 | J15: =SUM(C15:I15) -> 9
A16: F. | B16: METABOLIC ENDOCRINE SYSTEM (Diabetes, Hyperthyroidism, Hypothyroidism, Dyslipidemia) | C16: =SUM(January!C16,February!C16,March!C16,April!C16,May!C16,June!C16,July!C16,August!C16,September!C16,October!C16,November!C16,December!C16) -> 3 | D16: =SUM(January!D15,February!D15,March!D15,April!D15,May!D15,June!D15,July!D15,August!D15,September!D16,October!D16,November!D16,December!D16) -> 2 | E16: =SUM(January!E15,February!E15,March!E15,April!E15,May!E15,June!E15,July!E15,August!E15,September!E16,October!E16,November!E16,December!E16) -> 0 | F16: =SUM(January!F15,February!F15,March!F15,April!F15,May!F15,June!F15,July!F15,August!F15,September!F16,October!F16,November!F16,December!F16) -> 0 | G16: =SUM(January!G15,February!G15,March!G15,April!G15,May!G15,June!G15,July!G15,August!G15,September!G16,October!G16,November!G16,December!G16) -> 0 | H16: =SUM(January!H15,February!H15,March!H15,April!H15,May!H15,June!H15,July!H15,August!H15,September!H16,October!H16,November!H16,December!H16) -> 0 | I16: =SUM(January!I15,February!I15,March!I15,April!I15,May!I15,June!I15,July!I15,August!I15,September!I16,October!I16,November!I16,December!I16) -> 1 | J16: =SUM(C16:I16) -> 6
A17: G. | B17: CARDIOVASCULAR SYSTEM (Chest pain, Hypertension, Hypotension, Arrhythmias, Bradycardia, Tachycardia) | C17: =SUM(January!C17,February!C17,March!C17,April!C17,May!C17,June!C17,July!C17,August!C17,September!C17,October!C17,November!C17,December!C17) -> 14 | D17: =SUM(January!D16,February!D16,March!D16,April!D16,May!D16,June!D16,July!D16,August!D16,September!D17,October!D17,November!D17,December!D17) -> 15 | E17: =SUM(January!E16,February!E16,March!E16,April!E16,May!E16,June!E16,July!E16,August!E16,September!E17,October!E17,November!E17,December!E17) -> 1 | F17: =SUM(January!F16,February!F16,March!F16,April!F16,May!F16,June!F16,July!F16,August!F16,September!F17,October!F17,November!F17,December!F17) -> 0 | G17: =SUM(January!G16,February!G16,March!G16,April!G16,May!G16,June!G16,July!G16,August!G16,September!G17,October!G17,November!G17,December!G17) -> 2 | H17: =SUM(January!H16,February!H16,March!H16,April!H16,May!H16,June!H16,July!H16,August!H16,September!H17,October!H17,November!H17,December!H17) -> 1 | I17: =SUM(January!I16,February!I16,March!I16,April!I16,May!I16,June!I16,July!I16,August!I16,September!I17,October!I17,November!I17,December!I17) -> 1 | J17: =SUM(C17:I17) -> 34
A18: H. | B18: EYES, EARS, NOSE & THROAT DISORDERS (Sty, Fungal or Bacterial Infection, Foreign body,Vertigo, Otitis Media/Externa, Sinusitis, Epistaxis, Pharyngitis, Laryngitis, Tonsillitis, Rhinitis) | C18: =SUM(January!C18,February!C18,March!C18,April!C18,May!C18,June!C18,July!C18,August!C18,September!C18,October!C18,November!C18,December!C18) -> 0 | D18: =SUM(January!D18,February!D18,March!D18,April!D18,May!D18,June!D18,July!D18,August!D18,September!D18,October!D18,November!D18,December!D18) -> 1 | E18: =SUM(January!E18,February!E18,March!E18,April!E18,May!E18,June!E18,July!E18,August!E18,September!E18,October!E18,November!E18,December!E18) -> 0 | F18: =SUM(January!F18,February!F18,March!F18,April!F18,May!F18,June!F18,July!F18,August!F18,September!F18,October!F18,November!F18,December!F18) -> 1 | G18: =SUM(January!G18,February!G18,March!G18,April!G18,May!G18,June!G18,July!G18,August!G18,September!G18,October!G18,November!G18,December!G18) -> 3 | H18: =SUM(January!H18,February!H18,March!H18,April!H18,May!H18,June!H18,July!H18,August!H18,September!H18,October!H18,November!H18,December!H18) -> 0 | I18: =SUM(January!I18,February!I18,March!I18,April!I18,May!I18,June!I18,July!I18,August!I18,September!I18,October!I18,November!I18,December!I18) -> 0 | J18: =SUM(January!J18,February!J18,March!J18,April!J18,May!J18,June!J18,July!J18,August!J18,September!J18,October!J18,November!J18,December!J18) -> 5
A19: I. | B19: COMMUNICABLE DISEASES (Conjunctivitis, Boils, Measles, Chicken Pox, Mumps, Hepatitis, Tuberculosis, Leptospirosis, COVID Suspect, Viral Exanthem | C19: =SUM(January!C19,February!C19,March!C19,April!C19,May!C19,June!C19,July!C19,August!C19,September!C19,October!C19,November!C19,December!C19) -> 0 | D19: =SUM(January!D19,February!D19,March!D19,April!D19,May!D19,June!D19,July!D19,August!D19,September!D19,October!D19,November!D19,December!D19) -> 0 | E19: =SUM(January!E19,February!E19,March!E19,April!E19,May!E19,June!E19,July!E19,August!E19,September!E19,October!E19,November!E19,December!E19) -> 0 | F19: =SUM(January!F19,February!F19,March!F19,April!F19,May!F19,June!F19,July!F19,August!F19,September!F19,October!F19,November!F19,December!F19) -> 0 | G19: =SUM(January!G19,February!G19,March!G19,April!G19,May!G19,June!G19,July!G19,August!G19,September!G19,October!G19,November!G19,December!G19) -> 1 | H19: =SUM(January!H19,February!H19,March!H19,April!H19,May!H19,June!H19,July!H19,August!H19,September!H19,October!H19,November!H19,December!H19) -> 0 | I19: =SUM(January!I19,February!I19,March!I19,April!I19,May!I19,June!I19,July!I19,August!I19,September!I19,October!I19,November!I19,December!I19) -> 0 | J19: =SUM(January!J19,February!J19,March!J19,April!J19,May!J19,June!J19,July!J19,August!J19,September!J19,October!J19,November!J19,December!J19) -> 1
A20: J. | B20: BLOOD DISORDERS (Anemia, Pallor, ) | C20: =SUM(January!C20,February!C20,March!C20,April!C20,May!C20,June!C20,July!C20,August!C20,September!C20,October!C20,November!C20,December!C20) -> 19 | D20: =SUM(January!D20,February!D20,March!D20,April!D20,May!D20,June!D20,July!D20,August!D20,September!D20,October!D20,November!D20,December!D20) -> 7 | E20: =SUM(January!E20,February!E20,March!E20,April!E20,May!E20,June!E20,July!E20,August!E20,September!E20,October!E20,November!E20,December!E20) -> 1 | F20: =SUM(January!F20,February!F20,March!F20,April!F20,May!F20,June!F20,July!F20,August!F20,September!F20,October!F20,November!F20,December!F20) -> 2 | G20: =SUM(January!G20,February!G20,March!G20,April!G20,May!G20,June!G20,July!G20,August!G20,September!G20,October!G20,November!G20,December!G20) -> 7 | H20: =SUM(January!H20,February!H20,March!H20,April!H20,May!H20,June!H20,July!H20,August!H20,September!H20,October!H20,November!H20,December!H20) -> 0 | I20: =SUM(January!I20,February!I20,March!I20,April!I20,May!I20,June!I20,July!I20,August!I20,September!I20,October!I20,November!I20,December!I20) -> 2 | J20: =SUM(January!J20,February!J20,March!J20,April!J20,May!J20,June!J20,July!J20,August!J20,September!J20,October!J20,November!J20,December!J20) -> 38
A21: K. | B21: NEUROLOGICAL DISORDERS (Hyperventilation, Anxiety attack, Panic Attack, Headache, Migraine, Syncope, Dizziness, Epilepsy, Seizure, Insomnia) | C21: =SUM(January!C21,February!C21,March!C21,April!C21,May!C21,June!C21,July!C21,August!C21,September!C21,October!C21,November!C21,December!C21) -> 36 | D21: =SUM(January!D21,February!D21,March!D21,April!D21,May!D21,June!D21,July!D21,August!D21,September!D21,October!D21,November!D21,December!D21) -> 14 | E21: =SUM(January!E21,February!E21,March!E21,April!E21,May!E21,June!E21,July!E21,August!E21,September!E21,October!E21,November!E21,December!E21) -> 12 | F21: =SUM(January!F21,February!F21,March!F21,April!F21,May!F21,June!F21,July!F21,August!F21,September!F21,October!F21,November!F21,December!F21) -> 4 | G21: =SUM(January!G21,February!G21,March!G21,April!G21,May!G21,June!G21,July!G21,August!G21,September!G21,October!G21,November!G21,December!G21) -> 2 | H21: =SUM(January!H21,February!H21,March!H21,April!H21,May!H21,June!H21,July!H21,August!H21,September!H21,October!H21,November!H21,December!H21) -> 0 | I21: =SUM(January!I21,February!I21,March!I21,April!I21,May!I21,June!I21,July!I21,August!I21,September!I21,October!I21,November!I21,December!I21) -> 1 | J21: =SUM(January!J21,February!J21,March!J21,April!J21,May!J21,June!J21,July!J21,August!J21,September!J21,October!J21,November!J21,December!J21) -> 69
